<sdf version='1.7'>
  <world name='default'>
    <model name='ground_plane'>
      <static>1</static>
      <link name='link'>
        <collision name='collision'>
          <geometry>
            <plane>
              <normal>0 0 1</normal>
              <size>100 100</size>
            </plane>
          </geometry>
          <surface>
            <contact>
              <collide_bitmask>65535</collide_bitmask>
              <ode/>
            </contact>
            <friction>
              <ode>
                <mu>100</mu>
                <mu2>50</mu2>
              </ode>
              <torsional>
                <ode/>
              </torsional>
            </friction>
            <bounce/>
          </surface>
          <max_contacts>10</max_contacts>
        </collision>
        <visual name='visual'>
          <cast_shadows>0</cast_shadows>
          <geometry>
            <plane>
              <normal>0 0 1</normal>
              <size>100 100</size>
            </plane>
          </geometry>
          <material>
            <script>
              <uri>file://media/materials/scripts/gazebo.material</uri>
              <name>Gazebo/Grey</name>
            </script>
          </material>
        </visual>
        <self_collide>0</self_collide>
        <enable_wind>0</enable_wind>
        <kinematic>0</kinematic>
      </link>
    </model>
    <light name='sun' type='directional'>
      <cast_shadows>1</cast_shadows>
      <pose>0 0 10 0 -0 0</pose>
      <diffuse>0.8 0.8 0.8 1</diffuse>
      <specular>0.2 0.2 0.2 1</specular>
      <attenuation>
        <range>1000</range>
        <constant>0.9</constant>
        <linear>0.01</linear>
        <quadratic>0.001</quadratic>
      </attenuation>
      <direction>-0.5 0.1 -0.9</direction>
      <spot>
        <inner_angle>0</inner_angle>
        <outer_angle>0</outer_angle>
        <falloff>0</falloff>
      </spot>
    </light>
    <physics type='ode'>
      <real_time_update_rate>1000</real_time_update_rate>
      <max_step_size>0.001</max_step_size>
      <real_time_factor>1</real_time_factor>
    </physics>
    <gravity>0 0 -9.81</gravity>
    <gui fullscreen='0'>
      <camera name='user_camera'>
        <pose>0 0 4.8023 3.14159 1.57079 3.14159</pose>
        <view_controller>orbit</view_controller>
        <projection_type>perspective</projection_type>
      </camera>
    </gui>
    <magnetic_field>6e-06 2.3e-05 -4.2e-05</magnetic_field>
    <atmosphere type='adiabatic'/>
    <scene>
      <ambient>0.4 0.4 0.4 1</ambient>
      <background>0.7 0.7 0.7 1</background>
      <shadows>1</shadows>
    </scene>
    <wind/>
    <spherical_coordinates>
      <surface_model>EARTH_WGS84</surface_model>
      <latitude_deg>0</latitude_deg>
      <longitude_deg>0</longitude_deg>
      <elevation>0</elevation>
      <heading_deg>0</heading_deg>
    </spherical_coordinates>
    <model name='panda'>
      <joint name='panda_to_world' type='fixed'>
        <pose relative_to='__model__'>0 0 0 0 -0 0</pose>
        <parent>world</parent>
        <child>panda_link0</child>
      </joint>
      <link name='panda_link0'>
        <pose relative_to='panda_to_world'>0 0 0 0 -0 0</pose>
        <inertial>
          <pose>0 0 0 0 -0 0</pose>
          <mass>3.06</mass>
          <inertia>
            <ixx>0.3</ixx>
            <ixy>0</ixy>
            <ixz>0</ixz>
            <iyy>0.3</iyy>
            <iyz>0</iyz>
            <izz>0.3</izz>
          </inertia>
        </inertial>
        <collision name='panda_link0_collision'>
          <pose>0 0 0 0 -0 0</pose>
          <geometry>
            <mesh>
              <scale>1 1 1</scale>
              <uri>/home/andrea/Demo_2_Panda_Control/ROS/panda_control/src/franka_panda_description/meshes/collision/link0.stl</uri>
            </mesh>
          </geometry>
          <max_contacts>10</max_contacts>
          <surface>
            <contact>
              <ode/>
            </contact>
            <bounce/>
            <friction>
              <torsional>
                <ode/>
              </torsional>
              <ode/>
            </friction>
          </surface>
        </collision>
        <visual name='panda_link0_visual'>
          <pose>0 0 0 0 -0 0</pose>
          <geometry>
            <mesh>
              <scale>1 1 1</scale>
              <uri>/home/andrea/Demo_2_Panda_Control/ROS/panda_control/src/franka_panda_description/meshes/visual/link0.dae</uri>
            </mesh>
          </geometry>
        </visual>
        <self_collide>0</self_collide>
        <enable_wind>0</enable_wind>
        <kinematic>0</kinematic>
      </link>
      <joint name='panda_joint1' type='revolute'>
        <pose relative_to='panda_link0'>0 0 0.333 0 -0 0</pose>
        <parent>panda_link0</parent>
        <child>panda_link1</child>
        <axis>
          <xyz>0 0 1</xyz>
          <limit>
            <lower>-2.8973</lower>
            <upper>2.8973</upper>
            <effort>87</effort>
            <velocity>2.175</velocity>
          </limit>
          <dynamics>
            <damping>10</damping>
            <friction>5</friction>
            <spring_reference>0</spring_reference>
            <spring_stiffness>0</spring_stiffness>
          </dynamics>
        </axis>
        <physics>
          <provide_feedback>1</provide_feedback>
          <ode>
            <implicit_spring_damper>1</implicit_spring_damper>
            <cfm_damping>1</cfm_damping>
            <limit>
              <cfm>0</cfm>
              <erp>0.2</erp>
            </limit>
            <provide_feedback>1</provide_feedback>
          </ode>
        </physics>
      </joint>
      <link name='panda_link1'>
        <pose relative_to='panda_joint1'>0 0 0 0 -0 0</pose>
        <inertial>
          <pose>0.003875 0.002081 -0.175 0 -0 0</pose>
          <mass>4.97068</mass>
          <inertia>
            <ixx>0.70337</ixx>
            <ixy>-0.000139</ixy>
            <ixz>0.006772</ixz>
            <iyy>0.70661</iyy>
            <iyz>0.019169</iyz>
            <izz>0.009117</izz>
          </inertia>
        </inertial>
        <collision name='panda_link1_collision'>
          <pose>0 0 0 0 -0 0</pose>
          <geometry>
            <mesh>
              <scale>1 1 1</scale>
              <uri>/home/andrea/Demo_2_Panda_Control/ROS/panda_control/src/franka_panda_description/meshes/collision/link1.stl</uri>
            </mesh>
          </geometry>
          <surface>
            <contact>
              <ode/>
            </contact>
            <friction>
              <ode/>
              <torsional>
                <ode/>
              </torsional>
            </friction>
            <bounce/>
          </surface>
          <max_contacts>10</max_contacts>
        </collision>
        <visual name='panda_link1_visual'>
          <pose>0 0 0 0 -0 0</pose>
          <geometry>
            <mesh>
              <scale>1 1 1</scale>
              <uri>/home/andrea/Demo_2_Panda_Control/ROS/panda_control/src/franka_panda_description/meshes/visual/link1.dae</uri>
            </mesh>
          </geometry>
        </visual>
        <self_collide>1</self_collide>
        <sensor name='panda_link1_contact' type='contact'>
          <update_rate>50</update_rate>
          <always_on>1</always_on>
          <contact>
            <collision>panda_link1_collision</collision>
            <topic>__default_topic__</topic>
          </contact>
          <plugin name='link1_bumper' filename='libgazebo_ros_bumper.so'>
            <bumperTopicName>panda_link1_collision</bumperTopicName>
            <frameName>panda_link1</frameName>
            <robotNamespace>/</robotNamespace>
          </plugin>
        </sensor>
        <enable_wind>0</enable_wind>
        <kinematic>0</kinematic>
      </link>
      <joint name='panda_joint2' type='revolute'>
        <pose relative_to='panda_link1'>0 0 0 -1.5708 0 0</pose>
        <parent>panda_link1</parent>
        <child>panda_link2</child>
        <axis>
          <xyz>0 0 1</xyz>
          <limit>
            <lower>-1.7628</lower>
            <upper>1.7628</upper>
            <effort>87</effort>
            <velocity>2.175</velocity>
          </limit>
          <dynamics>
            <damping>5</damping>
            <friction>2</friction>
            <spring_reference>0</spring_reference>
            <spring_stiffness>0</spring_stiffness>
          </dynamics>
        </axis>
        <physics>
          <provide_feedback>1</provide_feedback>
          <ode>
            <implicit_spring_damper>1</implicit_spring_damper>
            <cfm_damping>1</cfm_damping>
            <limit>
              <cfm>0</cfm>
              <erp>0.2</erp>
            </limit>
            <provide_feedback>1</provide_feedback>
          </ode>
        </physics>
      </joint>
      <link name='panda_link2'>
        <pose relative_to='panda_joint2'>0 0 0 0 -0 0</pose>
        <inertial>
          <pose>-0.003141 -0.02872 0.003495 0 -0 0</pose>
          <mass>0.646926</mass>
          <inertia>
            <ixx>0.007962</ixx>
            <ixy>-0.003925</ixy>
            <ixz>0.010254</ixz>
            <iyy>0.02811</iyy>
            <iyz>0.000704</iyz>
            <izz>0.025995</izz>
          </inertia>
        </inertial>
        <collision name='panda_link2_collision'>
          <pose>0 0 0 0 -0 0</pose>
          <geometry>
            <mesh>
              <scale>1 1 1</scale>
              <uri>/home/andrea/Demo_2_Panda_Control/ROS/panda_control/src/franka_panda_description/meshes/collision/link2.stl</uri>
            </mesh>
          </geometry>
          <surface>
            <contact>
              <ode/>
            </contact>
            <friction>
              <ode/>
              <torsional>
                <ode/>
              </torsional>
            </friction>
            <bounce/>
          </surface>
          <max_contacts>10</max_contacts>
        </collision>
        <visual name='panda_link2_visual'>
          <pose>0 0 0 0 -0 0</pose>
          <geometry>
            <mesh>
              <scale>1 1 1</scale>
              <uri>/home/andrea/Demo_2_Panda_Control/ROS/panda_control/src/franka_panda_description/meshes/visual/link2.dae</uri>
            </mesh>
          </geometry>
        </visual>
        <self_collide>1</self_collide>
        <sensor name='panda_link2_contact' type='contact'>
          <update_rate>50</update_rate>
          <always_on>1</always_on>
          <contact>
            <collision>panda_link2_collision</collision>
            <topic>__default_topic__</topic>
          </contact>
          <plugin name='link2_bumper' filename='libgazebo_ros_bumper.so'>
            <bumperTopicName>panda_link2_collision</bumperTopicName>
            <frameName>panda_link2</frameName>
            <robotNamespace>/</robotNamespace>
          </plugin>
        </sensor>
        <enable_wind>0</enable_wind>
        <kinematic>0</kinematic>
      </link>
      <joint name='panda_joint3' type='revolute'>
        <pose relative_to='panda_link2'>0 -0.316 0 1.5708 -0 0</pose>
        <parent>panda_link2</parent>
        <child>panda_link3</child>
        <axis>
          <xyz>0 0 1</xyz>
          <limit>
            <lower>-2.8973</lower>
            <upper>2.8973</upper>
            <effort>87</effort>
            <velocity>2.175</velocity>
          </limit>
          <dynamics>
            <damping>5</damping>
            <friction>2</friction>
            <spring_reference>0</spring_reference>
            <spring_stiffness>0</spring_stiffness>
          </dynamics>
        </axis>
        <physics>
          <provide_feedback>1</provide_feedback>
          <ode>
            <implicit_spring_damper>1</implicit_spring_damper>
            <cfm_damping>1</cfm_damping>
            <limit>
              <cfm>0</cfm>
              <erp>0.2</erp>
            </limit>
            <provide_feedback>1</provide_feedback>
          </ode>
        </physics>
      </joint>
      <link name='panda_link3'>
        <pose relative_to='panda_joint3'>0 0 0 0 -0 0</pose>
        <inertial>
          <pose>0.027518 0.039252 -0.066502 0 -0 0</pose>
          <mass>3.2286</mass>
          <inertia>
            <ixx>0.037242</ixx>
            <ixy>-0.004761</ixy>
            <ixz>-0.011396</ixz>
            <iyy>0.036155</iyy>
            <iyz>-0.012805</iyz>
            <izz>0.01083</izz>
          </inertia>
        </inertial>
        <collision name='panda_link3_collision'>
          <pose>0 0 0 0 -0 0</pose>
          <geometry>
            <mesh>
              <scale>1 1 1</scale>
              <uri>/home/andrea/Demo_2_Panda_Control/ROS/panda_control/src/franka_panda_description/meshes/collision/link3.stl</uri>
            </mesh>
          </geometry>
          <surface>
            <contact>
              <ode/>
            </contact>
            <friction>
              <ode/>
              <torsional>
                <ode/>
              </torsional>
            </friction>
            <bounce/>
          </surface>
          <max_contacts>10</max_contacts>
        </collision>
        <visual name='panda_link3_visual'>
          <pose>0 0 0 0 -0 0</pose>
          <geometry>
            <mesh>
              <scale>1 1 1</scale>
              <uri>/home/andrea/Demo_2_Panda_Control/ROS/panda_control/src/franka_panda_description/meshes/visual/link3.dae</uri>
            </mesh>
          </geometry>
        </visual>
        <self_collide>1</self_collide>
        <sensor name='panda_link3_contact' type='contact'>
          <update_rate>50</update_rate>
          <always_on>1</always_on>
          <contact>
            <collision>panda_link3_collision</collision>
            <topic>__default_topic__</topic>
          </contact>
          <plugin name='link3_bumper' filename='libgazebo_ros_bumper.so'>
            <bumperTopicName>panda_link3_collision</bumperTopicName>
            <frameName>panda_link3</frameName>
            <robotNamespace>/</robotNamespace>
          </plugin>
        </sensor>
        <enable_wind>0</enable_wind>
        <kinematic>0</kinematic>
      </link>
      <joint name='panda_joint4' type='revolute'>
        <pose relative_to='panda_link3'>0.0825 0 0 1.5708 -0 0</pose>
        <parent>panda_link3</parent>
        <child>panda_link4</child>
        <axis>
          <xyz>0 0 1</xyz>
          <limit>
            <lower>-3.0718</lower>
            <upper>-0.0698</upper>
            <effort>87</effort>
            <velocity>2.175</velocity>
          </limit>
          <dynamics>
            <damping>1</damping>
            <friction>0.5</friction>
            <spring_reference>0</spring_reference>
            <spring_stiffness>0</spring_stiffness>
          </dynamics>
        </axis>
        <physics>
          <provide_feedback>1</provide_feedback>
          <ode>
            <implicit_spring_damper>1</implicit_spring_damper>
            <cfm_damping>1</cfm_damping>
            <limit>
              <cfm>0</cfm>
              <erp>0.2</erp>
            </limit>
            <provide_feedback>1</provide_feedback>
          </ode>
        </physics>
      </joint>
      <link name='panda_link4'>
        <pose relative_to='panda_joint4'>0 0 0 0 -0 0</pose>
        <inertial>
          <pose>-0.05317 0.104419 0.027454 0 -0 0</pose>
          <mass>3.5879</mass>
          <inertia>
            <ixx>0.025853</ixx>
            <ixy>0.007796</ixy>
            <ixz>-0.001332</ixz>
            <iyy>0.019552</iyy>
            <iyz>0.008641</iyz>
            <izz>0.028323</izz>
          </inertia>
        </inertial>
        <collision name='panda_link4_collision'>
          <pose>0 0 0 0 -0 0</pose>
          <geometry>
            <mesh>
              <scale>1 1 1</scale>
              <uri>/home/andrea/Demo_2_Panda_Control/ROS/panda_control/src/franka_panda_description/meshes/collision/link4.stl</uri>
            </mesh>
          </geometry>
          <surface>
            <contact>
              <ode/>
            </contact>
            <friction>
              <ode/>
              <torsional>
                <ode/>
              </torsional>
            </friction>
            <bounce/>
          </surface>
          <max_contacts>10</max_contacts>
        </collision>
        <visual name='panda_link4_visual'>
          <pose>0 0 0 0 -0 0</pose>
          <geometry>
            <mesh>
              <scale>1 1 1</scale>
              <uri>/home/andrea/Demo_2_Panda_Control/ROS/panda_control/src/franka_panda_description/meshes/visual/link4.dae</uri>
            </mesh>
          </geometry>
        </visual>
        <self_collide>1</self_collide>
        <sensor name='panda_link4_contact' type='contact'>
          <update_rate>50</update_rate>
          <always_on>1</always_on>
          <contact>
            <collision>panda_link4_collision</collision>
            <topic>__default_topic__</topic>
          </contact>
          <plugin name='link4_bumper' filename='libgazebo_ros_bumper.so'>
            <bumperTopicName>panda_link4_collision</bumperTopicName>
            <frameName>panda_link4</frameName>
            <robotNamespace>/</robotNamespace>
          </plugin>
        </sensor>
        <enable_wind>0</enable_wind>
        <kinematic>0</kinematic>
      </link>
      <joint name='panda_joint5' type='revolute'>
        <pose relative_to='panda_link4'>-0.0825 0.384 0 -1.5708 0 0</pose>
        <parent>panda_link4</parent>
        <child>panda_link5</child>
        <axis>
          <xyz>0 0 1</xyz>
          <limit>
            <lower>-2.8973</lower>
            <upper>2.8973</upper>
            <effort>12</effort>
            <velocity>2.61</velocity>
          </limit>
          <dynamics>
            <damping>2</damping>
            <friction>1</friction>
            <spring_reference>0</spring_reference>
            <spring_stiffness>0</spring_stiffness>
          </dynamics>
        </axis>
        <physics>
          <provide_feedback>1</provide_feedback>
          <ode>
            <implicit_spring_damper>1</implicit_spring_damper>
            <cfm_damping>1</cfm_damping>
            <limit>
              <cfm>0</cfm>
              <erp>0.2</erp>
            </limit>
            <provide_feedback>1</provide_feedback>
          </ode>
        </physics>
      </joint>
      <link name='panda_link5'>
        <pose relative_to='panda_joint5'>0 0 0 0 -0 0</pose>
        <inertial>
          <pose>-0.011953 0.041065 -0.038437 0 -0 0</pose>
          <mass>1.22595</mass>
          <inertia>
            <ixx>0.035549</ixx>
            <ixy>-0.002117</ixy>
            <ixz>-0.004037</ixz>
            <iyy>0.029474</iyy>
            <iyz>0.000229</iyz>
            <izz>0.008627</izz>
          </inertia>
        </inertial>
        <collision name='panda_link5_collision'>
          <pose>0 0 0 0 -0 0</pose>
          <geometry>
            <mesh>
              <scale>1 1 1</scale>
              <uri>/home/andrea/Demo_2_Panda_Control/ROS/panda_control/src/franka_panda_description/meshes/collision/link5.stl</uri>
            </mesh>
          </geometry>
          <surface>
            <contact>
              <ode/>
            </contact>
            <friction>
              <ode/>
              <torsional>
                <ode/>
              </torsional>
            </friction>
            <bounce/>
          </surface>
          <max_contacts>10</max_contacts>
        </collision>
        <visual name='panda_link5_visual'>
          <pose>0 0 0 0 -0 0</pose>
          <geometry>
            <mesh>
              <scale>1 1 1</scale>
              <uri>/home/andrea/Demo_2_Panda_Control/ROS/panda_control/src/franka_panda_description/meshes/visual/link5.dae</uri>
            </mesh>
          </geometry>
        </visual>
        <self_collide>1</self_collide>
        <sensor name='panda_link5_contact' type='contact'>
          <update_rate>50</update_rate>
          <always_on>1</always_on>
          <contact>
            <collision>panda_link5_collision</collision>
            <topic>__default_topic__</topic>
          </contact>
          <plugin name='link5_bumper' filename='libgazebo_ros_bumper.so'>
            <bumperTopicName>panda_link5_collision</bumperTopicName>
            <frameName>panda_link5</frameName>
            <robotNamespace>/</robotNamespace>
          </plugin>
        </sensor>
        <enable_wind>0</enable_wind>
        <kinematic>0</kinematic>
      </link>
      <joint name='panda_joint6' type='revolute'>
        <pose relative_to='panda_link5'>0 0 0 1.5708 -0 0</pose>
        <parent>panda_link5</parent>
        <child>panda_link6</child>
        <axis>
          <xyz>0 0 1</xyz>
          <limit>
            <lower>-0.0175</lower>
            <upper>3.7525</upper>
            <effort>12</effort>
            <velocity>2.61</velocity>
          </limit>
          <dynamics>
            <damping>1</damping>
            <friction>0.5</friction>
            <spring_reference>0</spring_reference>
            <spring_stiffness>0</spring_stiffness>
          </dynamics>
        </axis>
        <physics>
          <provide_feedback>1</provide_feedback>
          <ode>
            <implicit_spring_damper>1</implicit_spring_damper>
            <cfm_damping>1</cfm_damping>
            <limit>
              <cfm>0</cfm>
              <erp>0.2</erp>
            </limit>
            <provide_feedback>1</provide_feedback>
          </ode>
        </physics>
      </joint>
      <link name='panda_link6'>
        <pose relative_to='panda_joint6'>0 0 0 0 -0 0</pose>
        <inertial>
          <pose>0.060149 -0.014117 -0.010517 0 -0 0</pose>
          <mass>1.66656</mass>
          <inertia>
            <ixx>0.001964</ixx>
            <ixy>0.000109</ixy>
            <ixz>-0.001158</ixz>
            <iyy>0.004354</iyy>
            <iyz>0.000341</iyz>
            <izz>0.005433</izz>
          </inertia>
        </inertial>
        <collision name='panda_link6_collision'>
          <pose>0 0 0 0 -0 0</pose>
          <geometry>
            <mesh>
              <scale>1 1 1</scale>
              <uri>/home/andrea/Demo_2_Panda_Control/ROS/panda_control/src/franka_panda_description/meshes/collision/link6.stl</uri>
            </mesh>
          </geometry>
          <surface>
            <contact>
              <ode/>
            </contact>
            <friction>
              <ode/>
              <torsional>
                <ode/>
              </torsional>
            </friction>
            <bounce/>
          </surface>
          <max_contacts>10</max_contacts>
        </collision>
        <visual name='panda_link6_visual'>
          <pose>0 0 0 0 -0 0</pose>
          <geometry>
            <mesh>
              <scale>1 1 1</scale>
              <uri>/home/andrea/Demo_2_Panda_Control/ROS/panda_control/src/franka_panda_description/meshes/visual/link6.dae</uri>
            </mesh>
          </geometry>
        </visual>
        <self_collide>1</self_collide>
        <sensor name='panda_link6_contact' type='contact'>
          <update_rate>50</update_rate>
          <always_on>1</always_on>
          <contact>
            <collision>panda_link6_collision</collision>
            <topic>__default_topic__</topic>
          </contact>
          <plugin name='link6_bumper' filename='libgazebo_ros_bumper.so'>
            <bumperTopicName>panda_link6_collision</bumperTopicName>
            <frameName>panda_link6</frameName>
            <robotNamespace>/</robotNamespace>
          </plugin>
        </sensor>
        <enable_wind>0</enable_wind>
        <kinematic>0</kinematic>
      </link>
      <joint name='panda_joint7' type='revolute'>
        <pose relative_to='panda_link6'>0.088 0 0 1.5708 -0 0</pose>
        <parent>panda_link6</parent>
        <child>panda_link7</child>
        <axis>
          <xyz>0 0 1</xyz>
          <limit>
            <lower>-2.8973</lower>
            <upper>2.8973</upper>
            <effort>12</effort>
            <velocity>2.61</velocity>
          </limit>
          <dynamics>
            <damping>1</damping>
            <friction>0.5</friction>
            <spring_reference>0</spring_reference>
            <spring_stiffness>0</spring_stiffness>
          </dynamics>
        </axis>
        <physics>
          <provide_feedback>1</provide_feedback>
          <ode>
            <implicit_spring_damper>1</implicit_spring_damper>
            <cfm_damping>1</cfm_damping>
            <limit>
              <cfm>0</cfm>
              <erp>0.2</erp>
            </limit>
            <provide_feedback>1</provide_feedback>
          </ode>
        </physics>
        <sensor name='panda_joint7_force_torque' type='force_torque'>
          <always_on>1</always_on>
          <visualize>0</visualize>
          <force_torque>
            <frame>sensor</frame>
            <measure_direction>child_to_parent</measure_direction>
          </force_torque>
        </sensor>
      </joint>
      <link name='panda_link7'>
        <pose relative_to='panda_joint7'>0 0 0 0 -0 0</pose>
        <inertial>
          <pose>0.005815 -0.001597 0.097957 0 -0 0</pose>
          <mass>1.46552</mass>
          <inertia>
            <ixx>0.0170713</ixx>
            <ixy>-0.00160235</ixy>
            <ixz>-0.000943568</ixz>
            <iyy>0.0146046</iyy>
            <iyz>-0.000883539</iyz>
            <izz>0.00842183</izz>
          </inertia>
        </inertial>
        <collision name='panda_link7_collision'>
          <pose>0 0 0 0 -0 0</pose>
          <geometry>
            <mesh>
              <scale>1 1 1</scale>
              <uri>/home/andrea/Demo_2_Panda_Control/ROS/panda_control/src/franka_panda_description/meshes/collision/link7.stl</uri>
            </mesh>
          </geometry>
          <surface>
            <contact>
              <ode/>
            </contact>
            <friction>
              <ode/>
              <torsional>
                <ode/>
              </torsional>
            </friction>
            <bounce/>
          </surface>
          <max_contacts>10</max_contacts>
        </collision>
        <collision name='panda_link7_fixed_joint_lump__panda_hand_collision_1'>
          <pose>0 0 0.107 0 0 -0.785398</pose>
          <geometry>
            <mesh>
              <scale>1 1 1</scale>
              <uri>/home/andrea/Demo_2_Panda_Control/ROS/panda_control/src/franka_panda_description/meshes/collision/hand.stl</uri>
            </mesh>
          </geometry>
          <max_contacts>10</max_contacts>
          <surface>
            <contact>
              <ode/>
            </contact>
            <bounce/>
            <friction>
              <torsional>
                <ode/>
              </torsional>
              <ode/>
            </friction>
          </surface>
        </collision>
        <visual name='panda_link7_visual'>
          <pose>0 0 0 0 -0 0</pose>
          <geometry>
            <mesh>
              <scale>1 1 1</scale>
              <uri>/home/andrea/Demo_2_Panda_Control/ROS/panda_control/src/franka_panda_description/meshes/visual/link7.dae</uri>
            </mesh>
          </geometry>
        </visual>
        <visual name='panda_link7_fixed_joint_lump__panda_hand_visual_1'>
          <pose>0 0 0.107 0 0 -0.785398</pose>
          <geometry>
            <mesh>
              <scale>1 1 1</scale>
              <uri>/home/andrea/Demo_2_Panda_Control/ROS/panda_control/src/franka_panda_description/meshes/visual/hand.dae</uri>
            </mesh>
          </geometry>
        </visual>
        <self_collide>1</self_collide>
        <sensor name='panda_link7_contact' type='contact'>
          <update_rate>50</update_rate>
          <always_on>1</always_on>
          <contact>
            <collision>panda_link7_collision</collision>
            <topic>__default_topic__</topic>
          </contact>
          <plugin name='link7_bumper' filename='libgazebo_ros_bumper.so'>
            <bumperTopicName>panda_link7_collision</bumperTopicName>
            <frameName>panda_link7</frameName>
            <robotNamespace>/</robotNamespace>
          </plugin>
        </sensor>
        <enable_wind>0</enable_wind>
        <kinematic>0</kinematic>
      </link>
      <joint name='panda_finger_joint1' type='prismatic'>
        <pose relative_to='panda_link7'>0 0 0.1654 0 0 -0.785398</pose>
        <parent>panda_link7</parent>
        <child>panda_leftfinger</child>
        <axis>
          <xyz>0 1 0</xyz>
          <limit>
            <lower>0</lower>
            <upper>0.04</upper>
            <effort>20</effort>
            <velocity>0.2</velocity>
          </limit>
          <dynamics>
            <damping>500</damping>
            <friction>0</friction>
            <spring_reference>0</spring_reference>
            <spring_stiffness>0</spring_stiffness>
          </dynamics>
        </axis>
        <physics>
          <provide_feedback>1</provide_feedback>
          <ode>
            <implicit_spring_damper>1</implicit_spring_damper>
            <cfm_damping>1</cfm_damping>
            <limit>
              <cfm>0</cfm>
              <erp>0.2</erp>
            </limit>
            <provide_feedback>1</provide_feedback>
          </ode>
        </physics>
      </joint>
      <link name='panda_leftfinger'>
        <pose relative_to='panda_finger_joint1'>0 0 0 0 -0 0</pose>
        <inertial>
          <pose>0 0.014564 0.022794 0 -0 0</pose>
          <mass>0.1</mass>
          <inertia>
            <ixx>3.01221e-05</ixx>
            <ixy>0</ixy>
            <ixz>0</ixz>
            <iyy>2.95874e-05</iyy>
            <iyz>0</iyz>
            <izz>6.95125e-06</izz>
          </inertia>
        </inertial>
        <collision name='panda_leftfinger_collision'>
          <pose>0 0 0 0 -0 0</pose>
          <geometry>
            <mesh>
              <scale>1 1 1</scale>
              <uri>/home/andrea/Demo_2_Panda_Control/ROS/panda_control/src/franka_panda_description/meshes/collision/finger.stl</uri>
            </mesh>
          </geometry>
          <surface>
            <contact>
              <ode/>
            </contact>
            <friction>
              <ode/>
              <torsional>
                <ode/>
              </torsional>
            </friction>
            <bounce/>
          </surface>
          <max_contacts>10</max_contacts>
        </collision>
        <visual name='panda_leftfinger_visual'>
          <pose>0 0 0 0 -0 0</pose>
          <geometry>
            <mesh>
              <scale>1 1 1</scale>
              <uri>/home/andrea/Demo_2_Panda_Control/ROS/panda_control/src/franka_panda_description/meshes/visual/finger.dae</uri>
            </mesh>
          </geometry>
        </visual>
        <sensor name='panda_leftfinger_contact' type='contact'>
          <update_rate>50</update_rate>
          <always_on>1</always_on>
          <contact>
            <collision>panda_leftfinger_collision</collision>
            <topic>__default_topic__</topic>
          </contact>
          <plugin name='leftfinger_bumper' filename='libgazebo_ros_bumper.so'>
            <bumperTopicName>panda_leftfinger_collision</bumperTopicName>
            <frameName>panda_leftfinger</frameName>
            <robotNamespace>/</robotNamespace>
          </plugin>
        </sensor>
        <self_collide>0</self_collide>
        <enable_wind>0</enable_wind>
        <kinematic>0</kinematic>
      </link>
      <joint name='panda_finger_joint2' type='prismatic'>
        <pose relative_to='panda_link7'>0 0 0.1654 0 0 -0.785398</pose>
        <parent>panda_link7</parent>
        <child>panda_rightfinger</child>
        <axis>
          <xyz>0 -1 0</xyz>
          <limit>
            <lower>0</lower>
            <upper>0.04</upper>
            <effort>20</effort>
            <velocity>0.2</velocity>
          </limit>
          <dynamics>
            <damping>500</damping>
            <friction>0</friction>
            <spring_reference>0</spring_reference>
            <spring_stiffness>0</spring_stiffness>
          </dynamics>
        </axis>
        <physics>
          <provide_feedback>1</provide_feedback>
          <ode>
            <implicit_spring_damper>1</implicit_spring_damper>
            <cfm_damping>1</cfm_damping>
            <limit>
              <cfm>0</cfm>
              <erp>0.2</erp>
            </limit>
            <provide_feedback>1</provide_feedback>
          </ode>
        </physics>
      </joint>
      <link name='panda_rightfinger'>
        <pose relative_to='panda_finger_joint2'>0 0 0 0 -0 0</pose>
        <inertial>
          <pose>0 -0.014564 0.022794 0 -0 3.14159</pose>
          <mass>0.1</mass>
          <inertia>
            <ixx>3.01221e-05</ixx>
            <ixy>0</ixy>
            <ixz>0</ixz>
            <iyy>2.95874e-05</iyy>
            <iyz>0</iyz>
            <izz>6.95125e-06</izz>
          </inertia>
        </inertial>
        <collision name='panda_rightfinger_collision'>
          <pose>0 0 0 0 -0 3.14159</pose>
          <geometry>
            <mesh>
              <scale>1 1 1</scale>
              <uri>/home/andrea/Demo_2_Panda_Control/ROS/panda_control/src/franka_panda_description/meshes/collision/finger.stl</uri>
            </mesh>
          </geometry>
          <surface>
            <contact>
              <ode/>
            </contact>
            <friction>
              <ode/>
              <torsional>
                <ode/>
              </torsional>
            </friction>
            <bounce/>
          </surface>
          <max_contacts>10</max_contacts>
        </collision>
        <visual name='panda_rightfinger_visual'>
          <pose>0 0 0 0 -0 3.14159</pose>
          <geometry>
            <mesh>
              <scale>1 1 1</scale>
              <uri>/home/andrea/Demo_2_Panda_Control/ROS/panda_control/src/franka_panda_description/meshes/visual/finger.dae</uri>
            </mesh>
          </geometry>
        </visual>
        <sensor name='panda_rightfinger_contact' type='contact'>
          <update_rate>50</update_rate>
          <always_on>1</always_on>
          <contact>
            <collision>panda_rightfinger_collision</collision>
            <topic>__default_topic__</topic>
          </contact>
          <plugin name='rightfinger_bumper' filename='libgazebo_ros_bumper.so'>
            <bumperTopicName>panda_rightfinger_collision</bumperTopicName>
            <frameName>panda_rightfinger</frameName>
            <robotNamespace>/</robotNamespace>
          </plugin>
        </sensor>
        <self_collide>0</self_collide>
        <enable_wind>0</enable_wind>
        <kinematic>0</kinematic>
      </link>
      <plugin name='ft_sensor' filename='libgazebo_ros_ft_sensor.so'>
        <updateRate>30.0</updateRate>
        <topicName>/gazebo/robot/wrist/ft</topicName>
        <jointName>panda_joint7</jointName>
        <robotNamespace>/</robotNamespace>
      </plugin>
      <static>0</static>
      <plugin name='panda_ros_control' filename='libpanda_gazebo_ros_control.so'>
        <robotNamespace/>
        <robotSimType>panda_gazebo/PandaRobotHWSim</robotSimType>
        <controlPeriod>0.001</controlPeriod>
        <eStopTopic>sim_estop</eStopTopic>
      </plugin>
      <pose>0 0 0 0 -0 0</pose>
    </model>
    <model name='unit_box'>
      <pose>1.71688 -1.08983 0.5 0 -0 0</pose>
      <link name='link'>
        <inertial>
          <mass>1</mass>
          <inertia>
            <ixx>0.166667</ixx>
            <ixy>0</ixy>
            <ixz>0</ixz>
            <iyy>0.166667</iyy>
            <iyz>0</iyz>
            <izz>0.166667</izz>
          </inertia>
          <pose>0 0 0 0 -0 0</pose>
        </inertial>
        <collision name='collision'>
          <geometry>
            <box>
              <size>1 1 1</size>
            </box>
          </geometry>
          <max_contacts>10</max_contacts>
          <surface>
            <contact>
              <ode/>
            </contact>
            <bounce/>
            <friction>
              <torsional>
                <ode/>
              </torsional>
              <ode/>
            </friction>
          </surface>
        </collision>
        <visual name='visual'>
          <geometry>
            <box>
              <size>1 1 1</size>
            </box>
          </geometry>
          <material>
            <script>
              <name>Gazebo/Grey</name>
              <uri>file://media/materials/scripts/gazebo.material</uri>
            </script>
          </material>
        </visual>
        <self_collide>0</self_collide>
        <enable_wind>0</enable_wind>
        <kinematic>0</kinematic>
      </link>
    </model>
    <model name='unit_box_clone'>
      <pose>-0.062943 -0.867013 0.190866 0 -0 0</pose>
      <link name='link'>
        <inertial>
          <mass>1</mass>
          <inertia>
            <ixx>0.166667</ixx>
            <ixy>0</ixy>
            <ixz>0</ixz>
            <iyy>0.166667</iyy>
            <iyz>0</iyz>
            <izz>0.166667</izz>
          </inertia>
          <pose>0 0 0 0 -0 0</pose>
        </inertial>
        <collision name='collision'>
          <geometry>
            <box>
              <size>1 1 0.381731</size>
            </box>
          </geometry>
          <max_contacts>10</max_contacts>
          <surface>
            <contact>
              <ode/>
            </contact>
            <bounce/>
            <friction>
              <torsional>
                <ode/>
              </torsional>
              <ode/>
            </friction>
          </surface>
        </collision>
        <visual name='visual'>
          <geometry>
            <box>
              <size>1 1 0.381731</size>
            </box>
          </geometry>
          <material>
            <script>
              <name>Gazebo/Grey</name>
              <uri>file://media/materials/scripts/gazebo.material</uri>
            </script>
          </material>
        </visual>
        <self_collide>0</self_collide>
        <enable_wind>0</enable_wind>
        <kinematic>0</kinematic>
      </link>
    </model>
    <model name='wood_cube_5cm'>
      <link name='link'>
        <pose>0 0 0.025 0 -0 0</pose>
        <inertial>
          <mass>0.0565</mass>
          <inertia>
            <ixx>2.35417e-05</ixx>
            <ixy>0</ixy>
            <ixz>0</ixz>
            <iyy>2.35417e-05</iyy>
            <iyz>0</iyz>
            <izz>2.35417e-05</izz>
          </inertia>
          <pose>0 0 0 0 -0 0</pose>
        </inertial>
        <collision name='collision'>
          <geometry>
            <box>
              <size>0.05 0.05 0.05</size>
            </box>
          </geometry>
          <surface>
            <contact>
              <poissons_ratio>0.347</poissons_ratio>
              <elastic_modulus>8.8e+09</elastic_modulus>
              <ode>
                <kp>100000</kp>
                <kd>1</kd>
                <max_vel>1</max_vel>
                <min_depth>0.001</min_depth>
              </ode>
            </contact>
            <friction>
              <torsional>
                <coefficient>1</coefficient>
                <use_patch_radius>0</use_patch_radius>
                <surface_radius>0.05</surface_radius>
                <ode/>
              </torsional>
              <ode/>
            </friction>
            <bounce/>
          </surface>
          <max_contacts>10</max_contacts>
        </collision>
        <visual name='visual'>
          <geometry>
            <box>
              <size>0.05 0.05 0.05</size>
            </box>
          </geometry>
          <material>
            <script>
              <uri>file://media/materials/scripts/gazebo.material</uri>
              <name>Gazebo/Wood</name>
            </script>
          </material>
        </visual>
        <self_collide>0</self_collide>
        <enable_wind>0</enable_wind>
        <kinematic>0</kinematic>
      </link>
      <pose>0.515577 0.875852 0 0 -0 0</pose>
    </model>
    <model name='wood_cube_5cm_clone'>
      <link name='link'>
        <pose>0 0 0.025 0 -0 0</pose>
        <inertial>
          <mass>0.0565</mass>
          <inertia>
            <ixx>2.35417e-05</ixx>
            <ixy>0</ixy>
            <ixz>0</ixz>
            <iyy>2.35417e-05</iyy>
            <iyz>0</iyz>
            <izz>2.35417e-05</izz>
          </inertia>
          <pose>0 0 0 0 -0 0</pose>
        </inertial>
        <collision name='collision'>
          <geometry>
            <box>
              <size>0.05 0.05 0.05</size>
            </box>
          </geometry>
          <surface>
            <contact>
              <poissons_ratio>0.347</poissons_ratio>
              <elastic_modulus>8.8e+09</elastic_modulus>
              <ode>
                <kp>100000</kp>
                <kd>1</kd>
                <max_vel>1</max_vel>
                <min_depth>0.001</min_depth>
              </ode>
            </contact>
            <friction>
              <torsional>
                <coefficient>1</coefficient>
                <use_patch_radius>0</use_patch_radius>
                <surface_radius>0.05</surface_radius>
                <ode/>
              </torsional>
              <ode/>
            </friction>
            <bounce/>
          </surface>
          <max_contacts>10</max_contacts>
        </collision>
        <visual name='visual'>
          <geometry>
            <box>
              <size>0.05 0.05 0.05</size>
            </box>
          </geometry>
          <material>
            <script>
              <uri>file://media/materials/scripts/gazebo.material</uri>
              <name>Gazebo/Wood</name>
            </script>
          </material>
        </visual>
        <self_collide>0</self_collide>
        <enable_wind>0</enable_wind>
        <kinematic>0</kinematic>
      </link>
      <pose>0.97385 0.151834 0.38173 0 -0 0.030577</pose>
    </model>
    <model name='wood_cube_5cm_clone_0'>
      <link name='link'>
        <pose>0 0 0.025 0 -0 0</pose>
        <inertial>
          <mass>0.0565</mass>
          <inertia>
            <ixx>2.35417e-05</ixx>
            <ixy>0</ixy>
            <ixz>0</ixz>
            <iyy>2.35417e-05</iyy>
            <iyz>0</iyz>
            <izz>2.35417e-05</izz>
          </inertia>
          <pose>0 0 0 0 -0 0</pose>
        </inertial>
        <collision name='collision'>
          <geometry>
            <box>
              <size>0.05 0.05 0.05</size>
            </box>
          </geometry>
          <surface>
            <contact>
              <poissons_ratio>0.347</poissons_ratio>
              <elastic_modulus>8.8e+09</elastic_modulus>
              <ode>
                <kp>100000</kp>
                <kd>1</kd>
                <max_vel>1</max_vel>
                <min_depth>0.001</min_depth>
              </ode>
            </contact>
            <friction>
              <torsional>
                <coefficient>1</coefficient>
                <use_patch_radius>0</use_patch_radius>
                <surface_radius>0.05</surface_radius>
                <ode/>
              </torsional>
              <ode/>
            </friction>
            <bounce/>
          </surface>
          <max_contacts>10</max_contacts>
        </collision>
        <visual name='visual'>
          <geometry>
            <box>
              <size>0.05 0.05 0.05</size>
            </box>
          </geometry>
          <material>
            <script>
              <uri>file://media/materials/scripts/gazebo.material</uri>
              <name>Gazebo/Wood</name>
            </script>
          </material>
        </visual>
        <self_collide>0</self_collide>
        <enable_wind>0</enable_wind>
        <kinematic>0</kinematic>
      </link>
      <pose>0.912552 0.074834 0.38173 0 -0 0.030577</pose>
    </model>
    <model name='wood_cube_5cm_clone_1'>
      <link name='link'>
        <pose>0 0 0.025 0 -0 0</pose>
        <inertial>
          <mass>0.0565</mass>
          <inertia>
            <ixx>2.35417e-05</ixx>
            <ixy>0</ixy>
            <ixz>0</ixz>
            <iyy>2.35417e-05</iyy>
            <iyz>0</iyz>
            <izz>2.35417e-05</izz>
          </inertia>
          <pose>0 0 0 0 -0 0</pose>
        </inertial>
        <collision name='collision'>
          <geometry>
            <box>
              <size>0.05 0.05 0.05</size>
            </box>
          </geometry>
          <surface>
            <contact>
              <poissons_ratio>0.347</poissons_ratio>
              <elastic_modulus>8.8e+09</elastic_modulus>
              <ode>
                <kp>100000</kp>
                <kd>1</kd>
                <max_vel>1</max_vel>
                <min_depth>0.001</min_depth>
              </ode>
            </contact>
            <friction>
              <torsional>
                <coefficient>1</coefficient>
                <use_patch_radius>0</use_patch_radius>
                <surface_radius>0.05</surface_radius>
                <ode/>
              </torsional>
              <ode/>
            </friction>
            <bounce/>
          </surface>
          <max_contacts>10</max_contacts>
        </collision>
        <visual name='visual'>
          <geometry>
            <box>
              <size>0.05 0.05 0.05</size>
            </box>
          </geometry>
          <material>
            <script>
              <uri>file://media/materials/scripts/gazebo.material</uri>
              <name>Gazebo/Wood</name>
            </script>
          </material>
        </visual>
        <self_collide>0</self_collide>
        <enable_wind>0</enable_wind>
        <kinematic>0</kinematic>
      </link>
      <pose>0.828136 0.162555 0.38173 0 -0 0.030577</pose>
    </model>
    <model name='wood_cube_5cm_clone_2'>
      <link name='link'>
        <pose>0 0 0.025 0 -0 0</pose>
        <inertial>
          <mass>0.0565</mass>
          <inertia>
            <ixx>2.35417e-05</ixx>
            <ixy>0</ixy>
            <ixz>0</ixz>
            <iyy>2.35417e-05</iyy>
            <iyz>0</iyz>
            <izz>2.35417e-05</izz>
          </inertia>
          <pose>0 0 0 0 -0 0</pose>
        </inertial>
        <collision name='collision'>
          <geometry>
            <box>
              <size>0.05 0.05 0.05</size>
            </box>
          </geometry>
          <surface>
            <contact>
              <poissons_ratio>0.347</poissons_ratio>
              <elastic_modulus>8.8e+09</elastic_modulus>
              <ode>
                <kp>100000</kp>
                <kd>1</kd>
                <max_vel>1</max_vel>
                <min_depth>0.001</min_depth>
              </ode>
            </contact>
            <friction>
              <torsional>
                <coefficient>1</coefficient>
                <use_patch_radius>0</use_patch_radius>
                <surface_radius>0.05</surface_radius>
                <ode/>
              </torsional>
              <ode/>
            </friction>
            <bounce/>
          </surface>
          <max_contacts>10</max_contacts>
        </collision>
        <visual name='visual'>
          <geometry>
            <box>
              <size>0.05 0.05 0.05</size>
            </box>
          </geometry>
          <material>
            <script>
              <uri>file://media/materials/scripts/gazebo.material</uri>
              <name>Gazebo/Wood</name>
            </script>
          </material>
        </visual>
        <self_collide>0</self_collide>
        <enable_wind>0</enable_wind>
        <kinematic>0</kinematic>
      </link>
      <pose>1.20944 0.108291 0.38173 0 -0 0.030577</pose>
    </model>
    <model name='wood_cube_5cm_clone_3'>
      <link name='link'>
        <pose>0 0 0.025 0 -0 0</pose>
        <inertial>
          <mass>0.0565</mass>
          <inertia>
            <ixx>2.35417e-05</ixx>
            <ixy>0</ixy>
            <ixz>0</ixz>
            <iyy>2.35417e-05</iyy>
            <iyz>0</iyz>
            <izz>2.35417e-05</izz>
          </inertia>
          <pose>0 0 0 0 -0 0</pose>
        </inertial>
        <collision name='collision'>
          <geometry>
            <box>
              <size>0.05 0.05 0.05</size>
            </box>
          </geometry>
          <surface>
            <contact>
              <poissons_ratio>0.347</poissons_ratio>
              <elastic_modulus>8.8e+09</elastic_modulus>
              <ode>
                <kp>100000</kp>
                <kd>1</kd>
                <max_vel>1</max_vel>
                <min_depth>0.001</min_depth>
              </ode>
            </contact>
            <friction>
              <torsional>
                <coefficient>1</coefficient>
                <use_patch_radius>0</use_patch_radius>
                <surface_radius>0.05</surface_radius>
                <ode/>
              </torsional>
              <ode/>
            </friction>
            <bounce/>
          </surface>
          <max_contacts>10</max_contacts>
        </collision>
        <visual name='visual'>
          <geometry>
            <box>
              <size>0.05 0.05 0.05</size>
            </box>
          </geometry>
          <material>
            <script>
              <uri>file://media/materials/scripts/gazebo.material</uri>
              <name>Gazebo/Wood</name>
            </script>
          </material>
        </visual>
        <self_collide>0</self_collide>
        <enable_wind>0</enable_wind>
        <kinematic>0</kinematic>
      </link>
      <pose>0.9402 0.324657 0.38173 0 -0 0.030577</pose>
    </model>
    <model name='wood_cube_5cm_clone_4'>
      <link name='link'>
        <pose>0 0 0.025 0 -0 0</pose>
        <inertial>
          <mass>0.0565</mass>
          <inertia>
            <ixx>2.35417e-05</ixx>
            <ixy>0</ixy>
            <ixz>0</ixz>
            <iyy>2.35417e-05</iyy>
            <iyz>0</iyz>
            <izz>2.35417e-05</izz>
          </inertia>
          <pose>0 0 0 0 -0 0</pose>
        </inertial>
        <collision name='collision'>
          <geometry>
            <box>
              <size>0.05 0.05 0.05</size>
            </box>
          </geometry>
          <surface>
            <contact>
              <poissons_ratio>0.347</poissons_ratio>
              <elastic_modulus>8.8e+09</elastic_modulus>
              <ode>
                <kp>100000</kp>
                <kd>1</kd>
                <max_vel>1</max_vel>
                <min_depth>0.001</min_depth>
              </ode>
            </contact>
            <friction>
              <torsional>
                <coefficient>1</coefficient>
                <use_patch_radius>0</use_patch_radius>
                <surface_radius>0.05</surface_radius>
                <ode/>
              </torsional>
              <ode/>
            </friction>
            <bounce/>
          </surface>
          <max_contacts>10</max_contacts>
        </collision>
        <visual name='visual'>
          <geometry>
            <box>
              <size>0.05 0.05 0.05</size>
            </box>
          </geometry>
          <material>
            <script>
              <uri>file://media/materials/scripts/gazebo.material</uri>
              <name>Gazebo/Wood</name>
            </script>
          </material>
        </visual>
        <self_collide>0</self_collide>
        <enable_wind>0</enable_wind>
        <kinematic>0</kinematic>
      </link>
      <pose>0.818668 0.372001 0.38173 0 -0 0.030577</pose>
    </model>
    <model name='wood_cube_5cm_clone_5'>
      <link name='link'>
        <pose>0 0 0.025 0 -0 0</pose>
        <inertial>
          <mass>0.0565</mass>
          <inertia>
            <ixx>2.35417e-05</ixx>
            <ixy>0</ixy>
            <ixz>0</ixz>
            <iyy>2.35417e-05</iyy>
            <iyz>0</iyz>
            <izz>2.35417e-05</izz>
          </inertia>
          <pose>0 0 0 0 -0 0</pose>
        </inertial>
        <collision name='collision'>
          <geometry>
            <box>
              <size>0.05 0.05 0.05</size>
            </box>
          </geometry>
          <surface>
            <contact>
              <poissons_ratio>0.347</poissons_ratio>
              <elastic_modulus>8.8e+09</elastic_modulus>
              <ode>
                <kp>100000</kp>
                <kd>1</kd>
                <max_vel>1</max_vel>
                <min_depth>0.001</min_depth>
              </ode>
            </contact>
            <friction>
              <torsional>
                <coefficient>1</coefficient>
                <use_patch_radius>0</use_patch_radius>
                <surface_radius>0.05</surface_radius>
                <ode/>
              </torsional>
              <ode/>
            </friction>
            <bounce/>
          </surface>
          <max_contacts>10</max_contacts>
        </collision>
        <visual name='visual'>
          <geometry>
            <box>
              <size>0.05 0.05 0.05</size>
            </box>
          </geometry>
          <material>
            <script>
              <uri>file://media/materials/scripts/gazebo.material</uri>
              <name>Gazebo/Wood</name>
            </script>
          </material>
        </visual>
        <self_collide>0</self_collide>
        <enable_wind>0</enable_wind>
        <kinematic>0</kinematic>
      </link>
      <pose>1.14048 -0.005958 0.38173 0 -0 0.030577</pose>
    </model>
    <model name='wood_cube_5cm_clone_6'>
      <link name='link'>
        <pose>0 0 0.025 0 -0 0</pose>
        <inertial>
          <mass>0.0565</mass>
          <inertia>
            <ixx>2.35417e-05</ixx>
            <ixy>0</ixy>
            <ixz>0</ixz>
            <iyy>2.35417e-05</iyy>
            <iyz>0</iyz>
            <izz>2.35417e-05</izz>
          </inertia>
          <pose>0 0 0 0 -0 0</pose>
        </inertial>
        <collision name='collision'>
          <geometry>
            <box>
              <size>0.05 0.05 0.05</size>
            </box>
          </geometry>
          <surface>
            <contact>
              <poissons_ratio>0.347</poissons_ratio>
              <elastic_modulus>8.8e+09</elastic_modulus>
              <ode>
                <kp>100000</kp>
                <kd>1</kd>
                <max_vel>1</max_vel>
                <min_depth>0.001</min_depth>
              </ode>
            </contact>
            <friction>
              <torsional>
                <coefficient>1</coefficient>
                <use_patch_radius>0</use_patch_radius>
                <surface_radius>0.05</surface_radius>
                <ode/>
              </torsional>
              <ode/>
            </friction>
            <bounce/>
          </surface>
          <max_contacts>10</max_contacts>
        </collision>
        <visual name='visual'>
          <geometry>
            <box>
              <size>0.05 0.05 0.05</size>
            </box>
          </geometry>
          <material>
            <script>
              <uri>file://media/materials/scripts/gazebo.material</uri>
              <name>Gazebo/Wood</name>
            </script>
          </material>
        </visual>
        <self_collide>0</self_collide>
        <enable_wind>0</enable_wind>
        <kinematic>0</kinematic>
      </link>
      <pose>0.724728 0.265832 0.38173 0 -0 0.030577</pose>
    </model>
    <model name='wood_cube_5cm_clone_7'>
      <link name='link'>
        <pose>0 0 0.025 0 -0 0</pose>
        <inertial>
          <mass>0.0565</mass>
          <inertia>
            <ixx>2.35417e-05</ixx>
            <ixy>0</ixy>
            <ixz>0</ixz>
            <iyy>2.35417e-05</iyy>
            <iyz>0</iyz>
            <izz>2.35417e-05</izz>
          </inertia>
          <pose>0 0 0 0 -0 0</pose>
        </inertial>
        <collision name='collision'>
          <geometry>
            <box>
              <size>0.05 0.05 0.05</size>
            </box>
          </geometry>
          <surface>
            <contact>
              <poissons_ratio>0.347</poissons_ratio>
              <elastic_modulus>8.8e+09</elastic_modulus>
              <ode>
                <kp>100000</kp>
                <kd>1</kd>
                <max_vel>1</max_vel>
                <min_depth>0.001</min_depth>
              </ode>
            </contact>
            <friction>
              <torsional>
                <coefficient>1</coefficient>
                <use_patch_radius>0</use_patch_radius>
                <surface_radius>0.05</surface_radius>
                <ode/>
              </torsional>
              <ode/>
            </friction>
            <bounce/>
          </surface>
          <max_contacts>10</max_contacts>
        </collision>
        <visual name='visual'>
          <geometry>
            <box>
              <size>0.05 0.05 0.05</size>
            </box>
          </geometry>
          <material>
            <script>
              <uri>file://media/materials/scripts/gazebo.material</uri>
              <name>Gazebo/Wood</name>
            </script>
          </material>
        </visual>
        <self_collide>0</self_collide>
        <enable_wind>0</enable_wind>
        <kinematic>0</kinematic>
      </link>
      <pose>0.650287 0.173188 0.38173 0 -0 0.030577</pose>
    </model>
    <state world_name='default'>
      <sim_time>147 11000000</sim_time>
      <real_time>284 723236093</real_time>
      <wall_time>1684009366 977610710</wall_time>
      <iterations>147011</iterations>
      <model name='ground_plane'>
        <pose>0 0 0 0 -0 0</pose>
        <scale>1 1 1</scale>
        <link name='link'>
          <pose>0 0 0 0 -0 0</pose>
          <velocity>0 0 0 0 -0 0</velocity>
          <acceleration>0 0 0 0 -0 0</acceleration>
          <wrench>0 0 0 0 -0 0</wrench>
        </link>
      </model>
      <model name='panda'>
        <pose>-0 0 2.7e-05 -2.6e-05 -0 0</pose>
        <scale>1 1 1</scale>
        <link name='panda_leftfinger'>
          <pose>0.307307 0.000111 0.532804 3.1412 0.000112 0.00063</pose>
          <velocity>-0.000824 -1e-05 0.000585 0.000345 0.01176 0.003763</velocity>
          <acceleration>-2.07464 -0.010112 1.16163 -1.98613 -1.53569 -1.98629</acceleration>
          <wrench>-0.207464 -0.001011 0.116164 0 -0 0</wrench>
        </link>
        <link name='panda_link0'>
          <pose>-0 0 2.7e-05 -2.6e-05 -0 0</pose>
          <velocity>2e-06 -0 -0.006641 0.006392 -2.7e-05 -1.3e-05</velocity>
          <acceleration>0.003337 -0.000337 -13.2814 0.217351 -0.054517 -0.026149</acceleration>
          <wrench>0.010211 -0.001031 -40.641 0 -0 0</wrench>
        </link>
        <link name='panda_link1'>
          <pose>1e-06 8e-06 0.333026 -2.5e-05 2e-06 -1.1e-05</pose>
          <velocity>-0.000104 -0.002139 -0.00658 0.006382 -0.000276 -0.019512</velocity>
          <acceleration>-0.030479 -2.19521 -13.1315 0.198608 -0.550681 -1.34106</acceleration>
          <wrench>-0.151501 -10.9117 -65.2726 0 -0 0</wrench>
        </link>
        <link name='panda_link2'>
          <pose>0 8e-06 0.333026 -1.57085 -0.783452 3e-05</pose>
          <velocity>-5.3e-05 -0.002073 -0.006616 0.00724 0.012636 -0.019453</velocity>
          <acceleration>0.488847 -3.53343 -12.6138 2.43856 0.564637 0.228529</acceleration>
          <wrench>0.316248 -2.28587 -8.16021 0 -0 0</wrench>
        </link>
        <link name='panda_link3'>
          <pose>-0.223002 2.9e-05 0.556899 -0.000244 -0.783475 0.000344</pose>
          <velocity>0.002012 -0.001455 -0.003447 -0.016377 0.013856 0.002563</velocity>
          <acceleration>3.05557 -3.47737 -10.0208 -3.08335 1.12635 -2.74117</acceleration>
          <wrench>9.86523 -11.2271 -32.3533 0 -0 0</wrench>
        </link>
        <link name='panda_link4'>
          <pose>-0.16455 5e-05 0.615123 1.4531 1.56925 -0.117469</pose>
          <velocity>0.002546 -0.000493 -0.004189 -0.016497 -0.015579 -0.001781</velocity>
          <acceleration>3.33214 0.401922 -4.22295 2.2018 -1.16615 0.718441</acceleration>
          <wrench>11.9554 1.44206 -15.1515 0 -0 0</wrench>
        </link>
        <link name='panda_link5'>
          <pose>0.219323 0.000154 0.698213 -0.242166 1.56921 -0.241931</pose>
          <velocity>0.001248 0.000144 0.001746 0.000139 -0.01507 -0.002113</velocity>
          <acceleration>2.31181 0.447402 2.34358 -1.94137 0.356724 -1.82298</acceleration>
          <wrench>2.83417 0.548492 2.87311 0 -0 0</wrench>
        </link>
        <link name='panda_link6'>
          <pose>0.219323 0.000154 0.698213 1.57041 0.000101 0.000232</pose>
          <velocity>0.001233 0.000105 0.001719 0.000256 0.012662 -0.002201</velocity>
          <acceleration>2.15471 -0.047001 1.91945 1.54951 1.31995 -2.55924</acceleration>
          <wrench>3.59095 -0.078331 3.19887 0 -0 0</wrench>
        </link>
        <link name='panda_link7'>
          <pose>0.307323 0.000175 0.698204 3.14125 -0.000199 -0.784765</pose>
          <velocity>0.001229 -0.000105 0.000596 0.000526 0.012442 0.003385</velocity>
          <acceleration>0.039889 -0.071473 1.05851 0.386273 0.508237 1.6824</acceleration>
          <wrench>0.058459 -0.104745 1.55127 0 -0 0</wrench>
        </link>
        <link name='panda_rightfinger'>
          <pose>0.307307 0.000112 0.532804 3.1412 0.000113 0.00064</pose>
          <velocity>-0.000823 -1.9e-05 0.000592 0.000353 0.01172 0.002883</velocity>
          <acceleration>-2.26445 -0.023103 1.19525 -2.47318 -1.45783 2.66457</acceleration>
          <wrench>-0.226445 -0.00231 0.119525 0 -0 0</wrench>
        </link>
      </model>
      <model name='unit_box'>
        <pose>0.605618 0.100703 0.190859 -1.4e-05 1e-06 0.002503</pose>
        <scale>1 1 0.381731</scale>
        <link name='link'>
          <pose>0.605618 0.100703 0.190859 -1.4e-05 1e-06 0.002503</pose>
          <velocity>-0.000184 -0.002575 -0.006762 0.013493 -0.000968 1e-06</velocity>
          <acceleration>-0.18379 -2.57517 -6.76234 0.926952 -0.967726 0.001216</acceleration>
          <wrench>-0.18379 -2.57517 -6.76234 0 -0 0</wrench>
        </link>
      </model>
      <model name='unit_box_clone'>
        <pose>-0.776808 0.054094 0.190866 -0 -0 -0.004923</pose>
        <scale>1 1 1</scale>
        <link name='link'>
          <pose>-0.776808 0.054094 0.190866 -0 -0 -0.004923</pose>
          <velocity>0 0 0 0 -0 0</velocity>
          <acceleration>0 0 0 0 -0 0</acceleration>
          <wrench>0 0 0 0 -0 0</wrench>
        </link>
      </model>
      <model name='wood_cube_5cm'>
        <pose>0.35662 0.444726 0.395236 0.016726 -0.000497 0.00169</pose>
        <scale>1 1 1</scale>
        <link name='link'>
          <pose>0.356608 0.444308 0.420232 0.016726 -0.000497 0.00169</pose>
          <velocity>-0.000698 -0.004083 0.00423 -0.042698 -0.013185 1e-06</velocity>
          <acceleration>1.50219 -8.81678 10.7469 2.10907 0.162956 -1.52551</acceleration>
          <wrench>0.084874 -0.498148 0.6072 0 -0 0</wrench>
        </link>
      </model>
      <model name='wood_cube_5cm_clone'>
        <pose>0.297401 -0.149674 0.38166 0.000221 -5e-06 0.024035</pose>
        <scale>1 1 1</scale>
        <link name='link'>
          <pose>0.297401 -0.149679 0.40666 0.000221 -5e-06 0.024035</pose>
          <velocity>-0.000314 -0.004013 0.001918 -0.045482 0.002191 3e-06</velocity>
          <acceleration>-0.091292 -8.58445 3.59646 0.441009 0.1434 0.057552</acceleration>
          <wrench>-0.005158 -0.485021 0.2032 0 -0 0</wrench>
        </link>
      </model>
      <model name='wood_cube_5cm_clone_0'>
        <pose>0.301171 0.056514 0.381723 0.000213 -6e-06 0.028962</pose>
        <scale>1 1 1</scale>
        <link name='link'>
          <pose>0.301171 0.056509 0.406723 0.000213 -6e-06 0.028962</pose>
          <velocity>-0.000423 -0.003739 0.001027 -0.056461 -0.00219 4e-06</velocity>
          <acceleration>-0.189142 -8.04783 2.69526 0.970271 0.63065 -3.08131</acceleration>
          <wrench>-0.010687 -0.454702 0.152282 0 -0 0</wrench>
        </link>
      </model>
      <model name='wood_cube_5cm_clone_1'>
        <pose>0.294429 0.152909 0.381791 5.6e-05 0.000126 0.016548</pose>
        <scale>1 1 1</scale>
        <link name='link'>
          <pose>0.294432 0.152908 0.406791 5.6e-05 0.000126 0.016548</pose>
          <velocity>2e-05 -0.004794 3.3e-05 -0.013771 0.01557 0.000319</velocity>
          <acceleration>6.23448 -3.65204 0.556203 0.009368 1.49399 -2.05176</acceleration>
          <wrench>0.352248 -0.20634 0.031425 0 -0 0</wrench>
        </link>
      </model>
      <model name='wood_cube_5cm_clone_2'>
        <pose>0.21389 0.267635 0.381762 0.000219 -5e-06 0.02495</pose>
        <scale>1 1 1</scale>
        <link name='link'>
          <pose>0.21389 0.267629 0.406762 0.000219 -5e-06 0.02495</pose>
          <velocity>-0.000346 -0.003941 0.001658 -0.04836 0.000891 4e-06</velocity>
          <acceleration>-0.125723 -8.42495 3.32906 0.360214 -1.23803 0.0574</acceleration>
          <wrench>-0.007103 -0.47601 0.188092 0 -0 0</wrench>
        </link>
      </model>
      <model name='wood_cube_5cm_clone_3'>
        <pose>0.230563 -0.305876 0.381645 0.000158 3.3e-05 -0.028143</pose>
        <scale>1 1 1</scale>
        <link name='link'>
          <pose>0.230563 -0.30588 0.406645 0.000158 3.3e-05 -0.028143</pose>
          <velocity>-0.000712 -0.004063 0.003539 -0.0435 -0.013744 1e-06</velocity>
          <acceleration>1.39756 -8.65432 9.92844 -1.50852 -0.97243 1.85582</acceleration>
          <wrench>0.078962 -0.488969 0.560957 0 -0 0</wrench>
        </link>
      </model>
      <model name='wood_cube_5cm_clone_4'>
        <pose>0.289088 0.361402 0.381722 0.00024 -4e-06 0.019313</pose>
        <scale>1 1 1</scale>
        <link name='link'>
          <pose>0.289088 0.361396 0.406722 0.00024 -4e-06 0.019313</pose>
          <velocity>-0.000305 -0.004463 0.003771 -0.027501 0.002562 2e-06</velocity>
          <acceleration>-0.095371 -9.7327 5.51209 2.36368 -0.013348 0.049755</acceleration>
          <wrench>-0.005388 -0.549898 0.311433 0 -0 0</wrench>
        </link>
      </model>
      <model name='wood_cube_5cm_clone_5'>
        <pose>0.319645 -0.022058 0.381723 0.000206 -5e-06 0.01873</pose>
        <scale>1 1 1</scale>
        <link name='link'>
          <pose>0.319645 -0.022063 0.406723 0.000206 -5e-06 0.01873</pose>
          <velocity>-0.000405 -0.003466 0.000215 -0.067337 -0.00148 4e-06</velocity>
          <acceleration>-0.208379 -7.5648 1.89536 0.514477 1.40633 -3.08111</acceleration>
          <wrench>-0.011773 -0.427411 0.107088 0 -0 0</wrench>
        </link>
      </model>
      <model name='wood_cube_5cm_clone_6'>
        <pose>0.284779 0.284698 0.381725 0.00023 -1e-06 -0.040478</pose>
        <scale>1 1 1</scale>
        <link name='link'>
          <pose>0.284779 0.284693 0.406725 0.00023 -1e-06 -0.040478</pose>
          <velocity>-0.000304 -0.00422 0.002789 -0.037207 0.002573 2e-06</velocity>
          <acceleration>-0.464094 -9.1131 4.50054 -0.43658 -0.878621 -3.13877</acceleration>
          <wrench>-0.026221 -0.51489 0.254281 0 -0 0</wrench>
        </link>
      </model>
      <model name='wood_cube_5cm_clone_7'>
        <pose>0.271204 -0.255795 0.381731 0.000173 -0 -0.06781</pose>
        <scale>1 1 1</scale>
        <link name='link'>
          <pose>0.271203 -0.255799 0.406731 0.000173 -0 -0.06781</pose>
          <velocity>-0.000161 -0.002142 -0.003856 -0.12035 0.008272 6e-06</velocity>
          <acceleration>-0.363267 -5.16175 -2.08508 -1.39288 1.3762 -3.10327</acceleration>
          <wrench>-0.020525 -0.291639 -0.117807 0 -0 0</wrench>
        </link>
      </model>
      <light name='sun'>
        <pose>0 0 10 0 -0 0</pose>
      </light>
      <light name='user_point_light_0'>
        <pose>1.10629 0.794737 1 0 -0 0</pose>
      </light>
    </state>
    <light name='user_point_light_0' type='point'>
      <pose>1.10629 0.794737 1 0 -0 0</pose>
      <diffuse>0.5 0.5 0.5 1</diffuse>
      <specular>0.1 0.1 0.1 1</specular>
      <attenuation>
        <range>20</range>
        <constant>0.5</constant>
        <linear>0.01</linear>
        <quadratic>0.001</quadratic>
      </attenuation>
      <cast_shadows>0</cast_shadows>
      <direction>0 0 -1</direction>
    </light>
  </world>
</sdf>
